2024-06-01 18:35:30,621, ERROR: Exception on /hills/new [GET] [in /Users/lewis/Desktop/hill_tracker/venv/lib/python3.12/site-packages/flask/app.py:1414]
Traceback (most recent call last):
  File "/Users/lewis/Desktop/hill_tracker/venv/lib/python3.12/site-packages/sqlalchemy/engine/base.py", line 1971, in _exec_single_context
    self.dialect.do_execute(
  File "/Users/lewis/Desktop/hill_tracker/venv/lib/python3.12/site-packages/sqlalchemy/engine/default.py", line 919, in do_execute
    cursor.execute(statement, parameters)
sqlite3.OperationalError: no such column: hill_info.difficulty

The above exception was the direct cause of the following exception:

Traceback (most recent call last):
  File "/Users/lewis/Desktop/hill_tracker/venv/lib/python3.12/site-packages/flask/app.py", line 2190, in wsgi_app
    response = self.full_dispatch_request()
               ^^^^^^^^^^^^^^^^^^^^^^^^^^^^
  File "/Users/lewis/Desktop/hill_tracker/venv/lib/python3.12/site-packages/flask/app.py", line 1486, in full_dispatch_request
    rv = self.handle_user_exception(e)
         ^^^^^^^^^^^^^^^^^^^^^^^^^^^^^
  File "/Users/lewis/Desktop/hill_tracker/venv/lib/python3.12/site-packages/flask/app.py", line 1484, in full_dispatch_request
    rv = self.dispatch_request()
         ^^^^^^^^^^^^^^^^^^^^^^^
  File "/Users/lewis/Desktop/hill_tracker/venv/lib/python3.12/site-packages/flask/app.py", line 1469, in dispatch_request
    return self.ensure_sync(self.view_functions[rule.endpoint])(**view_args)
           ^^^^^^^^^^^^^^^^^^^^^^^^^^^^^^^^^^^^^^^^^^^^^^^^^^^^^^^^^^^^^^^^^
  File "/Users/lewis/Desktop/hill_tracker/app/routes.py", line 107, in add_new_hill
    all_hills = HillInfo.query.all()
                ^^^^^^^^^^^^^^^^^^^^
  File "/Users/lewis/Desktop/hill_tracker/venv/lib/python3.12/site-packages/sqlalchemy/orm/query.py", line 2673, in all
    return self._iter().all()  # type: ignore
           ^^^^^^^^^^^^
  File "/Users/lewis/Desktop/hill_tracker/venv/lib/python3.12/site-packages/sqlalchemy/orm/query.py", line 2827, in _iter
    result: Union[ScalarResult[_T], Result[_T]] = self.session.execute(
                                                  ^^^^^^^^^^^^^^^^^^^^^
  File "/Users/lewis/Desktop/hill_tracker/venv/lib/python3.12/site-packages/sqlalchemy/orm/session.py", line 2306, in execute
    return self._execute_internal(
           ^^^^^^^^^^^^^^^^^^^^^^^
  File "/Users/lewis/Desktop/hill_tracker/venv/lib/python3.12/site-packages/sqlalchemy/orm/session.py", line 2191, in _execute_internal
    result: Result[Any] = compile_state_cls.orm_execute_statement(
                          ^^^^^^^^^^^^^^^^^^^^^^^^^^^^^^^^^^^^^^^^
  File "/Users/lewis/Desktop/hill_tracker/venv/lib/python3.12/site-packages/sqlalchemy/orm/context.py", line 293, in orm_execute_statement
    result = conn.execute(
             ^^^^^^^^^^^^^
  File "/Users/lewis/Desktop/hill_tracker/venv/lib/python3.12/site-packages/sqlalchemy/engine/base.py", line 1422, in execute
    return meth(
           ^^^^^
  File "/Users/lewis/Desktop/hill_tracker/venv/lib/python3.12/site-packages/sqlalchemy/sql/elements.py", line 514, in _execute_on_connection
    return connection._execute_clauseelement(
           ^^^^^^^^^^^^^^^^^^^^^^^^^^^^^^^^^^
  File "/Users/lewis/Desktop/hill_tracker/venv/lib/python3.12/site-packages/sqlalchemy/engine/base.py", line 1644, in _execute_clauseelement
    ret = self._execute_context(
          ^^^^^^^^^^^^^^^^^^^^^^
  File "/Users/lewis/Desktop/hill_tracker/venv/lib/python3.12/site-packages/sqlalchemy/engine/base.py", line 1850, in _execute_context
    return self._exec_single_context(
           ^^^^^^^^^^^^^^^^^^^^^^^^^^
  File "/Users/lewis/Desktop/hill_tracker/venv/lib/python3.12/site-packages/sqlalchemy/engine/base.py", line 1990, in _exec_single_context
    self._handle_dbapi_exception(
  File "/Users/lewis/Desktop/hill_tracker/venv/lib/python3.12/site-packages/sqlalchemy/engine/base.py", line 2357, in _handle_dbapi_exception
    raise sqlalchemy_exception.with_traceback(exc_info[2]) from e
  File "/Users/lewis/Desktop/hill_tracker/venv/lib/python3.12/site-packages/sqlalchemy/engine/base.py", line 1971, in _exec_single_context
    self.dialect.do_execute(
  File "/Users/lewis/Desktop/hill_tracker/venv/lib/python3.12/site-packages/sqlalchemy/engine/default.py", line 919, in do_execute
    cursor.execute(statement, parameters)
sqlalchemy.exc.OperationalError: (sqlite3.OperationalError) no such column: hill_info.difficulty
[SQL: SELECT hill_info.id AS hill_info_id, hill_info.title AS hill_info_title, hill_info.distance AS hill_info_distance, hill_info.height AS hill_info_height, hill_info.difficulty AS hill_info_difficulty, hill_info.latitude AS hill_info_latitude, hill_info.longitude AS hill_info_longitude 
FROM hill_info]
(Background on this error at: https://sqlalche.me/e/20/e3q8)
2024-06-01 18:35:42,650, INFO: startup [in /Users/lewis/Desktop/hill_tracker/app/__init__.py:29]
2024-06-01 18:35:48,976, INFO: startup [in /Users/lewis/Desktop/hill_tracker/app/__init__.py:29]
2024-06-01 18:36:01,533, INFO: startup [in /Users/lewis/Desktop/hill_tracker/app/__init__.py:29]
2024-06-01 18:36:07,066, INFO: startup [in /Users/lewis/Desktop/hill_tracker/app/__init__.py:29]
2024-06-01 18:36:10,957, INFO: startup [in /Users/lewis/Desktop/hill_tracker/app/__init__.py:29]
2024-06-01 20:58:49,604, INFO: startup [in /Users/lewis/Desktop/hill_tracker/app/__init__.py:29]
